Workbook

Sheet Inputs
A1: SliceMatic — Inputs (edit the yellow cells only)
A3: FIXED COSTS (Rs. / month)
A4: Kitchen rent | B4: 55000 | C4: 1,200 sq ft commercial lease
A5: Equipment EMI | B5: 14500 | C5: Oven, mixer, refrigeration — 36-mo loan
A6: Electricity | B6: 12600 | C6: ~1,800 units/month
A7: Gas / LPG | B7: 5550 | C7: 3 cylinders @ Rs.1,850
A8: Head chef | B8: 28000
A9: Kitchen helper | B9: 16500 | C9: min wage + ESI/PF
A10: Counter + billing staff | B10: 18000
A11: Delivery riders (2) | B11: 32000 | C11: fixed component only
A12: Internet + POS + SaaS | B12: 2800
A13: Marketing (fixed) | B13: 8000
A14: Packaging (fixed component) | B14: 4200
A15: Misc / contingency | B15: 5760 | C15: 3% maintenance/consumables
A16: TOTAL FIXED COSTS | B16: =SUM(B4:B15) | C16: auto-sum
A18: REVENUE DRIVERS
A19: Weekday days / month | B19: 22
A20: Weekend+holiday days / month | B20: 8
A21: Weekday orders / day | B21: 38
A22: Weekend orders / day | B22: 68
A23: Weekday AOV (ex-GST) | B23: 792
A24: Weekend AOV (ex-GST) | B24: 940
A26: VARIABLE COST PER ORDER
A27: Ingredient COGS / order | B27: 148
A28: Packaging / order | B28: 18
A29: Delivery incentive / order | B29: 22
A30: Payment gateway % | B30: 0.018 | C30: % of order value
A32: PRICING RULES
A33: GST rate | B33: 0.18
A34: Discount threshold (qty >=) | B34: 5
A35: Discount % | B35: 0.1
A37: CAPACITY & INVESTMENT
A38: Max orders / day (100% capacity) | B38: 80
A39: Planned utilisation % | B39: 0.6
A40: Initial investment | B40: 1500000
A43: LEGEND:
A44: Yellow = editable input
A45: Green = key result | Blue = computed

Sheet Dashboard
A1: SliceMatic — Live Metrics Dashboard
A2: All values computed from the Inputs sheet. Edit inputs there; these update automatically.
A4: MONTHLY VOLUME & REVENUE
A5: Monthly orders | B5: =Inputs!B19*Inputs!B21+Inputs!B20*Inputs!B22
A6: Avg orders / day | B6: =B5/(Inputs!B19+Inputs!B20)
A7: Monthly revenue (ex-GST) | B7: =Inputs!B19*Inputs!B21*Inputs!B23+Inputs!B20*Inputs!B22*Inputs!B24
A8: Blended AOV (ex-GST) | B8: =B7/B5
A9: GST collected (passed to Govt.) | B9: =B7*Inputs!B33
A10: Gross billed (incl GST) | B10: =B7+B9
A12: PER-ORDER ECONOMICS
A13: Gateway fee / order | B13: =B8*Inputs!B30
A14: Contribution margin / order | B14: =B8-Inputs!B27-Inputs!B28-Inputs!B29-B13
A15: Contribution margin % | B15: =B14/B8
A17: MONTHLY P&L
A18: Monthly contribution | B18: =B5*B14
A19: Less: total fixed costs | B19: =-Inputs!B16
A20: EBITDA (operating profit) | B20: =B18+B19
A21: Operating margin | B21: =B20/B7
A23: BREAK-EVEN
A24: Break-even orders / month | B24: =Inputs!B16/B14
A25: Break-even orders / day | B25: =B24/30
A26: Safety multiple (plan / break-even) | B26: =B6/B25
A27: Capacity utilisation (implied) | B27: =B6/Inputs!B38
A29: PAYBACK
A30: Simple payback (months) | B30: =Inputs!B40/B20 | C30: at current EBITDA; real ramp is slower

Sheet COGS & Margin
A1: COGS & Gross Margin by Pizza Type
A2: Edit yellow component costs and selling prices; totals & margins recalc.
A4: Component | B4: Margherita | C4: Farm House | D4: Cheese Burst | E4: Custom
A5: Pizza base ingredients | B5: 38 | C5: 45 | D5: 72 | E5: 50
A6: Sauce + seasoning | B6: 12 | C6: 14 | D6: 14 | E6: 13
A7: Cheese (mozzarella) | B7: 28 | C7: 32 | D7: 65 | E7: 38
A8: Pizza-specific toppings | B8: 8 | C8: 22 | D8: 18 | E8: 17
A9: Add-on topping (avg 1) | B9: 10 | C9: 10 | D9: 10 | E9: 10
A10: Packaging (box + bag) | B10: 18 | C10: 18 | D10: 18 | E10: 18
A11: Delivery variable | B11: 22 | C11: 22 | D11: 22 | E11: 22
A12: TOTAL COGS / pizza | B12: =SUM(B5:B11) | C12: =SUM(C5:C11) | D12: =SUM(D5:D11) | E12: =SUM(E5:E11)
A13: Selling price (base+pizza+1 topping) | B13: 397 | C13: 417 | D13: 447 | E13: 420
A14: Gross margin / pizza | B14: =B13-B12 | C14: =C13-C12 | D14: =D13-D12 | E14: =E13-E12
A15: Gross margin % | B15: =B14/B13 | C15: =C14/C13 | D15: =D14/D13 | E15: =E14/E13

Sheet Bill Calculator
A1: Single-Order Bill Calculator
A2: Plug in prices + quantity (yellow). Mirrors the app's pricing logic exactly.
A4: ORDER INPUTS
A5: Base price | B5: 229
A6: Pizza price | B6: 379
A7: Topping price | B7: 69
A8: Quantity (1-10) | B8: 5
A10: COMPUTED BILL
A11: Unit price (base+pizza+topping) | B11: =B5+B6+B7
A12: Subtotal (unit x qty) | B12: =B11*B8
A13: Discount | B13: =IF(B8>=Inputs!B34,B12*Inputs!B35,0)
A14: Post-discount subtotal | B14: =B12-B13
A15: GST | B15: =B14*Inputs!B33
A16: TOTAL PAYABLE | B16: =B14+B15

Sheet Scenarios
A1: Stress Tests — Challenge These Numbers
A2: Yellow = scenario inputs. Everything else recalculates from Inputs + Dashboard.
A4: Q1 — RENT SHOCK
A5: New monthly rent | B5: 70000
A6: New total fixed costs | B6: =Inputs!B16-Inputs!B4+B5
A7: New break-even orders / month | B7: =B6/Dashboard!B14
A8: New break-even orders / day | B8: =B7/30
A9: Rent that makes plan unviable | B9: =Dashboard!B5*Dashboard!B14-(Inputs!B16-Inputs!B4) | C9: rent where break-even = planned volume
A11: Q2 — AGGREGATOR (Zomato/Swiggy)
A12: Aggregator order share | B12: 0.4
A13: Aggregator commission % | B13: 0.25
A14: CM / aggregator order | B14: =Dashboard!B8-Inputs!B27-Inputs!B28-Dashboard!B8*B13 | C14: aggregator covers delivery + payment
A15: CM / direct order | B15: =Dashboard!B14
A16: Blended CM / order | B16: =B12*B14+(1-B12)*B15
A17: New break-even orders / day | B17: =Inputs!B16/B16/30
A19: Q3 — 3rd RIDER JUSTIFICATION
A20: 3rd rider cost / month | B20: 16000
A21: Deliveries / rider / day | B21: 33
A22: Extra orders/day to pay for rider | B22: =B20/Dashboard!B14/30 | C22: financial breakeven (trivial)
A23: 2-rider delivery capacity / day | B23: =2*B21
A24: Recommended hire trigger (orders/day) | B24: =0.85*B23 | C24: hire before fleet saturates (SLA)
A26: Q4 — DISCOUNT IMPACT (5-pizza order)
A27: Order quantity | B27: 5
A28: Food cost / pizza (Cheese Burst) | B28: ='COGS & Margin'!D12-Inputs!B28-Inputs!B29 | C28: from COGS sheet, ex pkg/delivery
A29: Unit selling price | B29: ='Bill Calculator'!B11
A30: Subtotal (ex-GST) | B30: =B29*B27
A31: Discount (10%) | B31: =B30*Inputs!B35
A32: Variable cost (food x qty + pkg x qty + 1 delivery) | B32: =B28*B27+Inputs!B28*B27+Inputs!B29
A33: CM without discount | B33: =B30-B32
A34: CM with discount | B34: =B30-B31-B32
A35: Contribution given up by discount | B35: =B33-B34
A37: Q5 — COGS INFLATION
A38: Ingredient inflation % | B38: 0.12
A39: New ingredient COGS / order | B39: =Inputs!B27*(1+B38)
A40: New CM / order | B40: =Dashboard!B8-B39-Inputs!B28-Inputs!B29-Dashboard!B8*Inputs!B30
A41: Orders/month to hold EBITDA | B41: =(Dashboard!B20+Inputs!B16)/B40
A42: Extra orders / day needed | B42: =(B41-Dashboard!B5)/30
A44: Q6 — BI METRICS FROM ORDER LOG
A45: 1. Basket / AOV analysis -> upsell & menu engineering (revenue drops to profit)
A46: 2. Demand by hour x day-of-week -> staff & rider scheduling (cut idle cost, hold SLA)
...
